Workbook

Sheet Raw_Data
A1: Train No | B1: Train Name | C1: Platform | D1: Scheduled Time | E1: Actual Time | F1: Delay (min) | G1: Traffic Density (%) | H1: Status | I1: Traffic Level | J1: Time of Day | K1: Delay Bucket
A2: 12619 | B2: Matsyagandha Express | C2: 1 | D2: 06:10 | E2: 06:14 | F2: 4 | G2: 42 | H2: =IF(F2="","",IF(F2<=5,"On Time","Delayed")) -> On Time | I2: =IF(G2="","",IF(G2<30,"Low",IF(G2<70,"Medium","High"))) -> Medium | J2: =IF(D2="","",IF(VALUE(LEFT(D2,2))<6,"Night",IF(VALUE(LEFT(D2,2))<12,"Morning",IF(VALUE(LEFT(D2,2))<17,"Afternoon",IF(VALUE(LEFT(D2,2))<21,"Evening","Night"))))) -> Morning | K2: =IF(F2="","",IF(F2<=5,"0-5 min",IF(F2<=15,"6-15 min",IF(F2<=25,"16-25 min","26+ min")))) -> 0-5 min
A3: 16536 | B3: Gomantak Express | C3: 2 | D3: 07:25 | E3: 07:41 | F3: 16 | G3: 78 | H3: =IF(F3="","",IF(F3<=5,"On Time","Delayed")) -> Delayed | I3: =IF(G3="","",IF(G3<30,"Low",IF(G3<70,"Medium","High"))) -> High | J3: =IF(D3="","",IF(VALUE(LEFT(D3,2))<6,"Night",IF(VALUE(LEFT(D3,2))<12,"Morning",IF(VALUE(LEFT(D3,2))<17,"Afternoon",IF(VALUE(LEFT(D3,2))<21,"Evening","Night"))))) -> Morning | K3: =IF(F3="","",IF(F3<=5,"0-5 min",IF(F3<=15,"6-15 min",IF(F3<=25,"16-25 min","26+ min")))) -> 16-25 min
A4: 12620 | B4: Matsyagandha Express | C4: 1 | D4: 09:05 | E4: 09:05 | F4: 0 | G4: 20 | H4: =IF(F4="","",IF(F4<=5,"On Time","Delayed")) -> On Time | I4: =IF(G4="","",IF(G4<30,"Low",IF(G4<70,"Medium","High"))) -> Low | J4: =IF(D4="","",IF(VALUE(LEFT(D4,2))<6,"Night",IF(VALUE(LEFT(D4,2))<12,"Morning",IF(VALUE(LEFT(D4,2))<17,"Afternoon",IF(VALUE(LEFT(D4,2))<21,"Evening","Night"))))) -> Morning | K4: =IF(F4="","",IF(F4<=5,"0-5 min",IF(F4<=15,"6-15 min",IF(F4<=25,"16-25 min","26+ min")))) -> 0-5 min
A5: 16515 | B5: Yesvantpur Express | C5: 3 | D5: 10:40 | E5: 10:47 | F5: 7 | G5: 55 | H5: =IF(F5="","",IF(F5<=5,"On Time","Delayed")) -> Delayed | I5: =IF(G5="","",IF(G5<30,"Low",IF(G5<70,"Medium","High"))) -> Medium | J5: =IF(D5="","",IF(VALUE(LEFT(D5,2))<6,"Night",IF(VALUE(LEFT(D5,2))<12,"Morning",IF(VALUE(LEFT(D5,2))<17,"Afternoon",IF(VALUE(LEFT(D5,2))<21,"Evening","Night"))))) -> Morning | K5: =IF(F5="","",IF(F5<=5,"0-5 min",IF(F5<=15,"6-15 min",IF(F5<=25,"16-25 min","26+ min")))) -> 6-15 min
A6: 17326 | B6: Vasco Patna Express | C6: 4 | D6: 12:15 | E6: 12:38 | F6: 23 | G6: 91 | H6: =IF(F6="","",IF(F6<=5,"On Time","Delayed")) -> Delayed | I6: =IF(G6="","",IF(G6<30,"Low",IF(G6<70,"Medium","High"))) -> High | J6: =IF(D6="","",IF(VALUE(LEFT(D6,2))<6,"Night",IF(VALUE(LEFT(D6,2))<12,"Morning",IF(VALUE(LEFT(D6,2))<17,"Afternoon",IF(VALUE(LEFT(D6,2))<21,"Evening","Night"))))) -> Afternoon | K6: =IF(F6="","",IF(F6<=5,"0-5 min",IF(F6<=15,"6-15 min",IF(F6<=25,"16-25 min","26+ min")))) -> 16-25 min
A7: 12977 | B7: Intercity Express | C7: 1 | D7: 13:50 | E7: 14:03 | F7: 13 | G7: 88 | H7: =IF(F7="","",IF(F7<=5,"On Time","Delayed")) -> Delayed | I7: =IF(G7="","",IF(G7<30,"Low",IF(G7<70,"Medium","High"))) -> High | J7: =IF(D7="","",IF(VALUE(LEFT(D7,2))<6,"Night",IF(VALUE(LEFT(D7,2))<12,"Morning",IF(VALUE(LEFT(D7,2))<17,"Afternoon",IF(VALUE(LEFT(D7,2))<21,"Evening","Night"))))) -> Afternoon | K7: =IF(F7="","",IF(F7<=5,"0-5 min",IF(F7<=15,"6-15 min",IF(F7<=25,"16-25 min","26+ min")))) -> 6-15 min
A8: 16345 | B8: Netravati Express | C8: 2 | D8: 15:20 | E8: 15:22 | F8: 2 | G8: 35 | H8: =IF(F8="","",IF(F8<=5,"On Time","Delayed")) -> On Time | I8: =IF(G8="","",IF(G8<30,"Low",IF(G8<70,"Medium","High"))) -> Medium | J8: =IF(D8="","",IF(VALUE(LEFT(D8,2))<6,"Night",IF(VALUE(LEFT(D8,2))<12,"Morning",IF(VALUE(LEFT(D8,2))<17,"Afternoon",IF(VALUE(LEFT(D8,2))<21,"Evening","Night"))))) -> Afternoon | K8: =IF(F8="","",IF(F8<=5,"0-5 min",IF(F8<=15,"6-15 min",IF(F8<=25,"16-25 min","26+ min")))) -> 0-5 min
A9: 12134 | B9: Mangala Express | C9: 3 | D9: 16:45 | E9: 16:45 | F9: 0 | G9: 18 | H9: =IF(F9="","",IF(F9<=5,"On Time","Delayed")) -> On Time | I9: =IF(G9="","",IF(G9<30,"Low",IF(G9<70,"Medium","High"))) -> Low | J9: =IF(D9="","",IF(VALUE(LEFT(D9,2))<6,"Night",IF(VALUE(LEFT(D9,2))<12,"Morning",IF(VALUE(LEFT(D9,2))<17,"Afternoon",IF(VALUE(LEFT(D9,2))<21,"Evening","Night"))))) -> Afternoon | K9: =IF(F9="","",IF(F9<=5,"0-5 min",IF(F9<=15,"6-15 min",IF(F9<=25,"16-25 min","26+ min")))) -> 0-5 min
A10: 16594 | B10: Karwar Express | C10: 4 | D10: 18:10 | E10: 18:29 | F10: 19 | G10: 82 | H10: =IF(F10="","",IF(F10<=5,"On Time","Delayed")) -> Delayed | I10: =IF(G10="","",IF(G10<30,"Low",IF(G10<70,"Medium","High"))) -> High | J10: =IF(D10="","",IF(VALUE(LEFT(D10,2))<6,"Night",IF(VALUE(LEFT(D10,2))<12,"Morning",IF(VALUE(LEFT(D10,2))<17,"Afternoon",IF(VALUE(LEFT(D10,2))<21,"Evening","Night"))))) -> Evening | K10: =IF(F10="","",IF(F10<=5,"0-5 min",IF(F10<=15,"6-15 min",IF(F10<=25,"16-25 min","26+ min")))) -> 16-25 min
A11: 17311 | B11: Amaravati Express | C11: 1 | D11: 19:35 | E11: 19:41 | F11: 6 | G11: 60 | H11: =IF(F11="","",IF(F11<=5,"On Time","Delayed")) -> Delayed | I11: =IF(G11="","",IF(G11<30,"Low",IF(G11<70,"Medium","High"))) -> Medium | J11: =IF(D11="","",IF(VALUE(LEFT(D11,2))<6,"Night",IF(VALUE(LEFT(D11,2))<12,"Morning",IF(VALUE(LEFT(D11,2))<17,"Afternoon",IF(VALUE(LEFT(D11,2))<21,"Evening","Night"))))) -> Evening | K11: =IF(F11="","",IF(F11<=5,"0-5 min",IF(F11<=15,"6-15 min",IF(F11<=25,"16-25 min","26+ min")))) -> 6-15 min
A12: 16597 | B12: Vivek Express | C12: 2 | D12: 21:00 | E12: 21:00 | F12: 0 | G12: 25 | H12: =IF(F12="","",IF(F12<=5,"On Time","Delayed")) -> On Time | I12: =IF(G12="","",IF(G12<30,"Low",IF(G12<70,"Medium","High"))) -> Low | J12: =IF(D12="","",IF(VALUE(LEFT(D12,2))<6,"Night",IF(VALUE(LEFT(D12,2))<12,"Morning",IF(VALUE(LEFT(D12,2))<17,"Afternoon",IF(VALUE(LEFT(D12,2))<21,"Evening","Night"))))) -> Night | K12: =IF(F12="","",IF(F12<=5,"0-5 min",IF(F12<=15,"6-15 min",IF(F12<=25,"16-25 min","26+ min")))) -> 0-5 min
A13: 12618 | B13: Mangalore Mail | C13: 3 | D13: 22:30 | E13: 22:52 | F13: 22 | G13: 95 | H13: =IF(F13="","",IF(F13<=5,"On Time","Delayed")) -> Delayed | I13: =IF(G13="","",IF(G13<30,"Low",IF(G13<70,"Medium","High"))) -> High | J13: =IF(D13="","",IF(VALUE(LEFT(D13,2))<6,"Night",IF(VALUE(LEFT(D13,2))<12,"Morning",IF(VALUE(LEFT(D13,2))<17,"Afternoon",IF(VALUE(LEFT(D13,2))<21,"Evening","Night"))))) -> Night | K13: =IF(F13="","",IF(F13<=5,"0-5 min",IF(F13<=15,"6-15 min",IF(F13<=25,"16-25 min","26+ min")))) -> 16-25 min
H14: =IF(F14="","",IF(F14<=5,"On Time","Delayed")) | I14: =IF(G14="","",IF(G14<30,"Low",IF(G14<70,"Medium","High"))) | J14: =IF(D14="","",IF(VALUE(LEFT(D14,2))<6,"Night",IF(VALUE(LEFT(D14,2))<12,"Morning",IF(VALUE(LEFT(D14,2))<17,"Afternoon",IF(VALUE(LEFT(D14,2))<21,"Evening","Night"))))) | K14: =IF(F14="","",IF(F14<=5,"0-5 min",IF(F14<=15,"6-15 min",IF(F14<=25,"16-25 min","26+ min"))))
H15: =IF(F15="","",IF(F15<=5,"On Time","Delayed")) | I15: =IF(G15="","",IF(G15<30,"Low",IF(G15<70,"Medium","High"))) | J15: =IF(D15="","",IF(VALUE(LEFT(D15,2))<6,"Night",IF(VALUE(LEFT(D15,2))<12,"Morning",IF(VALUE(LEFT(D15,2))<17,"Afternoon",IF(VALUE(LEFT(D15,2))<21,"Evening","Night"))))) | K15: =IF(F15="","",IF(F15<=5,"0-5 min",IF(F15<=15,"6-15 min",IF(F15<=25,"16-25 min","26+ min"))))
H16: =IF(F16="","",IF(F16<=5,"On Time","Delayed")) | I16: =IF(G16="","",IF(G16<30,"Low",IF(G16<70,"Medium","High"))) | J16: =IF(D16="","",IF(VALUE(LEFT(D16,2))<6,"Night",IF(VALUE(LEFT(D16,2))<12,"Morning",IF(VALUE(LEFT(D16,2))<17,"Afternoon",IF(VALUE(LEFT(D16,2))<21,"Evening","Night"))))) | K16: =IF(F16="","",IF(F16<=5,"0-5 min",IF(F16<=15,"6-15 min",IF(F16<=25,"16-25 min","26+ min"))))
H17: =IF(F17="","",IF(F17<=5,"On Time","Delayed")) | I17: =IF(G17="","",IF(G17<30,"Low",IF(G17<70,"Medium","High"))) | J17: =IF(D17="","",IF(VALUE(LEFT(D17,2))<6,"Night",IF(VALUE(LEFT(D17,2))<12,"Morning",IF(VALUE(LEFT(D17,2))<17,"Afternoon",IF(VALUE(LEFT(D17,2))<21,"Evening","Night"))))) | K17: =IF(F17="","",IF(F17<=5,"0-5 min",IF(F17<=15,"6-15 min",IF(F17<=25,"16-25 min","26+ min"))))
H18: =IF(F18="","",IF(F18<=5,"On Time","Delayed")) | I18: =IF(G18="","",IF(G18<30,"Low",IF(G18<70,"Medium","High"))) | J18: =IF(D18="","",IF(VALUE(LEFT(D18,2))<6,"Night",IF(VALUE(LEFT(D18,2))<12,"Morning",IF(VALUE(LEFT(D18,2))<17,"Afternoon",IF(VALUE(LEFT(D18,2))<21,"Evening","Night"))))) | K18: =IF(F18="","",IF(F18<=5,"0-5 min",IF(F18<=15,"6-15 min",IF(F18<=25,"16-25 min","26+ min"))))
H19: =IF(F19="","",IF(F19<=5,"On Time","Delayed")) | I19: =IF(G19="","",IF(G19<30,"Low",IF(G19<70,"Medium","High"))) | J19: =IF(D19="","",IF(VALUE(LEFT(D19,2))<6,"Night",IF(VALUE(LEFT(D19,2))<12,"Morning",IF(VALUE(LEFT(D19,2))<17,"Afternoon",IF(VALUE(LEFT(D19,2))<21,"Evening","Night"))))) | K19: =IF(F19="","",IF(F19<=5,"0-5 min",IF(F19<=15,"6-15 min",IF(F19<=25,"16-25 min","26+ min"))))
H20: =IF(F20="","",IF(F20<=5,"On Time","Delayed")) | I20: =IF(G20="","",IF(G20<30,"Low",IF(G20<70,"Medium","High"))) | J20: =IF(D20="","",IF(VALUE(LEFT(D20,2))<6,"Night",IF(VALUE(LEFT(D20,2))<12,"Morning",IF(VALUE(LEFT(D20,2))<17,"Afternoon",IF(VALUE(LEFT(D20,2))<21,"Evening","Night"))))) | K20: =IF(F20="","",IF(F20<=5,"0-5 min",IF(F20<=15,"6-15 min",IF(F20<=25,"16-25 min","26+ min"))))
H21: =IF(F21="","",IF(F21<=5,"On Time","Delayed")) | I21: =IF(G21="","",IF(G21<30,"Low",IF(G21<70,"Medium","High"))) | J21: =IF(D21="","",IF(VALUE(LEFT(D21,2))<6,"Night",IF(VALUE(LEFT(D21,2))<12,"Morning",IF(VALUE(LEFT(D21,2))<17,"Afternoon",IF(VALUE(LEFT(D21,2))<21,"Evening","Night"))))) | K21: =IF(F21="","",IF(F21<=5,"0-5 min",IF(F21<=15,"6-15 min",IF(F21<=25,"16-25 min","26+ min"))))
H22: =IF(F22="","",IF(F22<=5,"On Time","Delayed")) | I22: =IF(G22="","",IF(G22<30,"Low",IF(G22<70,"Medium","High"))) | J22: =IF(D22="","",IF(VALUE(LEFT(D22,2))<6,"Night",IF(VALUE(LEFT(D22,2))<12,"Morning",IF(VALUE(LEFT(D22,2))<17,"Afternoon",IF(VALUE(LEFT(D22,2))<21,"Evening","Night"))))) | K22: =IF(F22="","",IF(F22<=5,"0-5 min",IF(F22<=15,"6-15 min",IF(F22<=25,"16-25 min","26+ min"))))
H23: =IF(F23="","",IF(F23<=5,"On Time","Delayed")) | I23: =IF(G23="","",IF(G23<30,"Low",IF(G23<70,"Medium","High"))) | J23: =IF(D23="","",IF(VALUE(LEFT(D23,2))<6,"Night",IF(VALUE(LEFT(D23,2))<12,"Morning",IF(VALUE(LEFT(D23,2))<17,"Afternoon",IF(VALUE(LEFT(D23,2))<21,"Evening","Night"))))) | K23: =IF(F23="","",IF(F23<=5,"0-5 min",IF(F23<=15,"6-15 min",IF(F23<=25,"16-25 min","26+ min"))))
H24: =IF(F24="","",IF(F24<=5,"On Time","Delayed")) | I24: =IF(G24="","",IF(G24<30,"Low",IF(G24<70,"Medium","High"))) | J24: =IF(D24="","",IF(VALUE(LEFT(D24,2))<6,"Night",IF(VALUE(LEFT(D24,2))<12,"Morning",IF(VALUE(LEFT(D24,2))<17,"Afternoon",IF(VALUE(LEFT(D24,2))<21,"Evening","Night"))))) | K24: =IF(F24="","",IF(F24<=5,"0-5 min",IF(F24<=15,"6-15 min",IF(F24<=25,"16-25 min","26+ min"))))
H25: =IF(F25="","",IF(F25<=5,"On Time","Delayed")) | I25: =IF(G25="","",IF(G25<30,"Low",IF(G25<70,"Medium","High"))) | J25: =IF(D25="","",IF(VALUE(LEFT(D25,2))<6,"Night",IF(VALUE(LEFT(D25,2))<12,"Morning",IF(VALUE(LEFT(D25,2))<17,"Afternoon",IF(VALUE(LEFT(D25,2))<21,"Evening","Night"))))) | K25: =IF(F25="","",IF(F25<=5,"0-5 min",IF(F25<=15,"6-15 min",IF(F25<=25,"16-25 min","26+ min"))))
... H300: =IF(F300="","",IF(F300<=5,"On Time","Delayed")) | I300: =IF(G300="","",IF(G300<30,"Low",IF(G300<70,"Medium","High"))) | J300: =IF(D300="","",IF(VALUE(LEFT(D300,2))<6,"Night",IF(VALUE(LEFT(D300,2))<12,"Morning",IF(VALUE(LEFT(D300,2))<17,"Afternoon",IF(VALUE(LEFT(D300,2))<21,"Evening","Night"))))) | K300: =IF(F300="","",IF(F300<=5,"0-5 min",IF(F300<=15,"6-15 min",IF(F300<=25,"16-25 min","26+ min"))))
A303: Legend: Columns A-G (yellow) are written by the backend, one row per train. Columns H-K (Status, Traffic Level, Time of Day, Delay Bucket) are formulas that recalculate automatically — do not overwrite them. Backend should clear/replace rows 2+ in columns A-G only before writing new data.

Sheet Analysis
A1: Delay Analysis Summary
A3: Key Metrics
A4: Total Trains Recorded | B4: =COUNTA(Raw_Data!A2:A300) -> 12
A5: Average Delay (min) | B5: =IFERROR(AVERAGE(Raw_Data!F2:F300),0) -> 9.3333333
A6: Maximum Delay (min) | B6: =IFERROR(MAX(Raw_Data!F2:F300),0) -> 23
A7: Minimum Delay (min) | B7: =IFERROR(MIN(Raw_Data!F2:F300),0) -> 0
A8: On-Time Trains (≤ 5 min) | B8: =COUNTIF(Raw_Data!H2:H300,"On Time") -> 5
A9: Delayed Trains (> 5 min) | B9: =COUNTIF(Raw_Data!H2:H300,"Delayed") -> 7
A10: On-Time Percentage (%) | B10: =IFERROR(B8/B4*100,0) -> 41.666667
A13: Delay by Traffic Level
A14: Traffic Level | B14: Train Count | C14: Avg Delay (min)
A15: Low | B15: =COUNTIF(Raw_Data!$I$2:$I$300,A15) -> 3 | C15: =IFERROR(AVERAGEIF(Raw_Data!$I$2:$I$300,A15,Raw_Data!$F$2:$F$300),0) -> 0
A16: Medium | B16: =COUNTIF(Raw_Data!$I$2:$I$300,A16) -> 4 | C16: =IFERROR(AVERAGEIF(Raw_Data!$I$2:$I$300,A16,Raw_Data!$F$2:$F$300),0) -> 4.75
A17: High | B17: =COUNTIF(Raw_Data!$I$2:$I$300,A17) -> 5 | C17: =IFERROR(AVERAGEIF(Raw_Data!$I$2:$I$300,A17,Raw_Data!$F$2:$F$300),0) -> 18.6
A20: Train Status Split
A21: Status | B21: Count
A22: On Time | B22: =COUNTIF(Raw_Data!$H$2:$H$300,A22) -> 5
A23: Delayed | B23: =COUNTIF(Raw_Data!$H$2:$H$300,A23) -> 7
A26: Average Delay by Platform
A27: Platform | B27: Train Count | C27: Avg Delay (min)
A28: 1 | B28: =COUNTIF(Raw_Data!$C$2:$C$300,A28) -> 4 | C28: =IFERROR(AVERAGEIF(Raw_Data!$C$2:$C$300,A28,Raw_Data!$F$2:$F$300),0) -> 5.75
A29: 2 | B29: =COUNTIF(Raw_Data!$C$2:$C$300,A29) -> 3 | C29: =IFERROR(AVERAGEIF(Raw_Data!$C$2:$C$300,A29,Raw_Data!$F$2:$F$300),0) -> 6
A30: 3 | B30: =COUNTIF(Raw_Data!$C$2:$C$300,A30) -> 3 | C30: =IFERROR(AVERAGEIF(Raw_Data!$C$2:$C$300,A30,Raw_Data!$F$2:$F$300),0) -> 9.6666667
A31: 4 | B31: =COUNTIF(Raw_Data!$C$2:$C$300,A31) -> 2 | C31: =IFERROR(AVERAGEIF(Raw_Data!$C$2:$C$300,A31,Raw_Data!$F$2:$F$300),0) -> 21
A34: Average Delay by Time of Day
A35: Time of Day | B35: Train Count | C35: Avg Delay (min)
A36: Morning | B36: =COUNTIF(Raw_Data!$J$2:$J$300,A36) -> 4 | C36: =IFERROR(AVERAGEIF(Raw_Data!$J$2:$J$300,A36,Raw_Data!$F$2:$F$300),0) -> 6.75
A37: Afternoon | B37: =COUNTIF(Raw_Data!$J$2:$J$300,A37) -> 4 | C37: =IFERROR(AVERAGEIF(Raw_Data!$J$2:$J$300,A37,Raw_Data!$F$2:$F$300),0) -> 9.5
A38: Evening | B38: =COUNTIF(Raw_Data!$J$2:$J$300,A38) -> 2 | C38: =IFERROR(AVERAGEIF(Raw_Data!$J$2:$J$300,A38,Raw_Data!$F$2:$F$300),0) -> 12.5
A39: Night | B39: =COUNTIF(Raw_Data!$J$2:$J$300,A39) -> 2 | C39: =IFERROR(AVERAGEIF(Raw_Data!$J$2:$J$300,A39,Raw_Data!$F$2:$F$300),0) -> 11
A42: Delay Distribution
A43: Delay Bucket | B43: Train Count
A44: 0-5 min | B44: =COUNTIF(Raw_Data!$K$2:$K$300,A44) -> 5
A45: 6-15 min | B45: =COUNTIF(Raw_Data!$K$2:$K$300,A45) -> 3
A46: 16-25 min | B46: =COUNTIF(Raw_Data!$K$2:$K$300,A46) -> 4
A47: 26+ min | B47: =COUNTIF(Raw_Data!$K$2:$K$300,A47) -> 0
A50: Top 5 Most Delayed Trains
A51: Rank | B51: Train Name | C51: Delay (min)
A52: 1 | B52: =IFERROR(INDEX(Raw_Data!$B$2:$B$300,MATCH(C52,Raw_Data!$F$2:$F$300,0)),"") -> Vasco Patna Express | C52: =IFERROR(LARGE(Raw_Data!$F$2:$F$300,1),0) -> 23
A53: 2 | B53: =IFERROR(INDEX(Raw_Data!$B$2:$B$300,MATCH(C53,Raw_Data!$F$2:$F$300,0)),"") -> Mangalore Mail | C53: =IFERROR(LARGE(Raw_Data!$F$2:$F$300,2),0) -> 22
...

Sheet Dashboard
A1: MAQ Railway AI — Delay Analysis Dashboard
A2: Auto-updates when new rows are added to Raw_Data
